<?xml version="1.0" ?>
<robot name="all-4-export" xmlns:xacro="http://www.ros.org/wiki/xacro">

<xacro:include filename="$(find all-4-export_description)/urdf/materials.xacro" />
<xacro:include filename="$(find all-4-export_description)/urdf/all-4-export.trans" />
<xacro:include filename="$(find all-4-export_description)/urdf/all-4-export.gazebo" />
<link name="base_link">
  <inertial>
    <origin xyz="4.41128716381848e-15 0.02800546166274284 0.010778198398999333" rpy="0 0 0"/>
    <mass value="0.9811970901956754"/>
    <inertia ixx="0.000446" iyy="0.002408" izz="0.002531" ixy="0.0" iyz="-0.0" ixz="0.0"/>
  </inertial>
  <visual>
    <origin xyz="0 0 0" rpy="0 0 0"/>
    <geometry>
      <mesh filename="package://4-dof/meshes/base_link.stl" scale="0.001 0.001 0.001"/>
    </geometry>
    <material name="silver"/>
  </visual>
  <collision>
    <origin xyz="0 0 0" rpy="0 0 0"/>
    <geometry>
      <mesh filename="package://4-dof/meshes/base_link.stl" scale="0.001 0.001 0.001"/>
    </geometry>
  </collision>
</link>

<link name="MX-64R_v1__2__1">
  <inertial>
    <origin xyz="0.017451641868345052 0.011000000017253497 0.030092246470602525" rpy="0 0 0"/>
    <!-- mass from MX-64R spec sheet (robotis.com, 902-0065-000): 126g -->
    <mass value="0.126"/>
    <inertia ixx="4.344e-05" iyy="5.186e-05" izz="2.948e-05" ixy="0.0" iyz="0.0" ixz="-1.551e-06"/>
  </inertial>
  <visual>
    <origin xyz="0.06625 -0.017 -0.0148" rpy="0 0 0"/>
    <geometry>
      <mesh filename="package://4-dof/meshes/MX-64R_v1__2__1.stl" scale="0.001 0.001 0.001"/>
    </geometry>
    <material name="silver"/>
  </visual>
  <collision>
    <origin xyz="0.06625 -0.017 -0.0148" rpy="0 0 0"/>
    <geometry>
      <mesh filename="package://4-dof/meshes/MX-64R_v1__2__1.stl" scale="0.001 0.001 0.001"/>
    </geometry>
  </collision>
</link>

<link name="MX-64R_v1__1__1">
  <inertial>
    <origin xyz="-0.017451641868345052 0.010999999982746273 0.030092246470602525" rpy="0 0 0"/>
    <!-- mass from MX-64R spec sheet (robotis.com, 902-0065-000): 126g -->
    <mass value="0.126"/>
    <inertia ixx="4.344e-05" iyy="5.186e-05" izz="2.948e-05" ixy="0.0" iyz="-0.0" ixz="1.551e-06"/>
  </inertial>
  <visual>
    <origin xyz="-0.06625 -0.017 -0.0148" rpy="0 0 0"/>
    <geometry>
      <mesh filename="package://4-dof/meshes/MX-64R_v1__1__1.stl" scale="0.001 0.001 0.001"/>
    </geometry>
    <material name="silver"/>
  </visual>
  <collision>
    <origin xyz="-0.06625 -0.017 -0.0148" rpy="0 0 0"/>
    <geometry>
      <mesh filename="package://4-dof/meshes/MX-64R_v1__1__1.stl" scale="0.001 0.001 0.001"/>
    </geometry>
  </collision>
</link>

<link name="FR05-H101_v1__1__1">
  <inertial>
    <origin xyz="0.02550000000002023 -1.1796119636642288e-16 0.0256313146478562" rpy="0 0 0"/>
    <mass value="0.05198831685263556"/>
    <inertia ixx="1.3e-05" iyy="2.7e-05" izz="2.6e-05" ixy="0.0" iyz="0.0" ixz="-0.0"/>
  </inertial>
  <visual>
    <origin xyz="0.02575 -0.028 -0.0601" rpy="0 0 0"/>
    <geometry>
      <mesh filename="package://4-dof/meshes/FR05-H101_v1__1__1.stl" scale="0.001 0.001 0.001"/>
    </geometry>
    <material name="silver"/>
  </visual>
  <collision>
    <origin xyz="0.02575 -0.028 -0.0601" rpy="0 0 0"/>
    <geometry>
      <mesh filename="package://4-dof/meshes/FR05-H101_v1__1__1.stl" scale="0.001 0.001 0.001"/>
    </geometry>
  </collision>
</link>

<link name="FR05-B101_v1_1">
  <inertial>
    <origin xyz="-4.5090504680739274e-14 -0.0029557693246398953 0.0016902214716354585" rpy="0 0 0"/>
    <mass value="0.01879497598985593"/>
    <inertia ixx="2e-06" iyy="4e-06" izz="5e-06" ixy="0.0" iyz="0.0" ixz="-0.0"/>
  </inertial>
  <visual>
    <origin xyz="0.00025 -0.028 -0.0961" rpy="0 0 0"/>
    <geometry>
      <mesh filename="package://4-dof/meshes/FR05-B101_v1_1.stl" scale="0.001 0.001 0.001"/>
    </geometry>
    <material name="silver"/>
  </visual>
  <collision>
    <origin xyz="0.00025 -0.028 -0.0961" rpy="0 0 0"/>
    <geometry>
      <mesh filename="package://4-dof/meshes/FR05-B101_v1_1.stl" scale="0.001 0.001 0.001"/>
    </geometry>
  </collision>
</link>

<link name="MX-64R_v1_1">
  <inertial>
    <origin xyz="0.017300000017253583 -0.019207753529397596 0.017451641868345094" rpy="0 0 0"/>
    <!-- mass from MX-64R spec sheet (robotis.com, 902-0065-000): 126g -->
    <mass value="0.126"/>
    <inertia ixx="5.186e-05" iyy="2.948e-05" izz="4.344e-05" ixy="0.0" iyz="-1.551e-06" ixz="0.0"/>
  </inertial>
  <visual>
    <origin xyz="0.01755 -0.032 -0.1021" rpy="0 0 0"/>
    <geometry>
      <mesh filename="package://4-dof/meshes/MX-64R_v1_1.stl" scale="0.001 0.001 0.001"/>
    </geometry>
    <material name="silver"/>
  </visual>
  <collision>
    <origin xyz="0.01755 -0.032 -0.1021" rpy="0 0 0"/>
    <geometry>
      <mesh filename="package://4-dof/meshes/MX-64R_v1_1.stl" scale="0.001 0.001 0.001"/>
    </geometry>
  </collision>
</link>

<link name="FR05-H101_v1_1">
  <inertial>
    <origin xyz="2.024828872279616e-14 -1.3530843112619095e-16 0.010168685352143825" rpy="0 0 0"/>
    <mass value="0.05198831685263556"/>
    <inertia ixx="1.3e-05" iyy="2.7e-05" izz="2.6e-05" ixy="-0.0" iyz="-0.0" ixz="0.0"/>
  </inertial>
  <visual>
    <origin xyz="0.00025 -0.028 -0.1426" rpy="0 0 0"/>
    <geometry>
      <mesh filename="package://4-dof/meshes/FR05-H101_v1_1.stl" scale="0.001 0.001 0.001"/>
    </geometry>
    <material name="silver"/>
  </visual>
  <collision>
    <origin xyz="0.00025 -0.028 -0.1426" rpy="0 0 0"/>
    <geometry>
      <mesh filename="package://4-dof/meshes/FR05-H101_v1_1.stl" scale="0.001 0.001 0.001"/>
    </geometry>
  </collision>
</link>

<link name="arm_v9_1">
  <inertial>
    <origin xyz="0.02362282770461404 1.947747047686965e-05 0.05189568925169269" rpy="0 0 0"/>
    <!-- mass measured: arm_v9_1 = 27g -->
    <mass value="0.027"/>
    <inertia ixx="2.666e-05" iyy="3.21e-05" izz="1.077e-05" ixy="0.0" iyz="0.0" ixz="1.11e-07"/>
  </inertial>
  <visual>
    <origin xyz="0.02375 -0.028 -0.1674" rpy="0 0 0"/>
    <geometry>
      <mesh filename="package://4-dof/meshes/arm_v9_1.stl" scale="0.001 0.001 0.001"/>
    </geometry>
    <material name="silver"/>
  </visual>
  <collision>
    <origin xyz="0.02375 -0.028 -0.1674" rpy="0 0 0"/>
    <geometry>
      <mesh filename="package://4-dof/meshes/arm_v9_1.stl" scale="0.001 0.001 0.001"/>
    </geometry>
  </collision>
</link>

<link name="FR07-S101_v1__1__1">
  <inertial>
    <origin xyz="-2.0825301118992945e-14 0.008467333868896306 0.002214506791986759" rpy="0 0 0"/>
    <mass value="0.011446844551351427"/>
    <inertia ixx="1e-06" iyy="2e-06" izz="2e-06" ixy="0.0" iyz="-0.0" ixz="-0.0"/>
  </inertial>
  <visual>
    <origin xyz="0.00025 -0.02 -0.2614" rpy="0 0 0"/>
    <geometry>
      <mesh filename="package://4-dof/meshes/FR07-S101_v1__1__1.stl" scale="0.001 0.001 0.001"/>
    </geometry>
    <material name="silver"/>
  </visual>
  <collision>
    <origin xyz="0.00025 -0.02 -0.2614" rpy="0 0 0"/>
    <geometry>
      <mesh filename="package://4-dof/meshes/FR07-S101_v1__1__1.stl" scale="0.001 0.001 0.001"/>
    </geometry>
  </collision>
</link>

<link name="MX-28T_R_v1__1__1">
  <inertial>
    <origin xyz="0.015031845145486198 0.017984471617669542 0.014999999976589629" rpy="0 0 0"/>
    <!-- mass from MX-28T spec sheet (robotis.com, 902-0067-000): 72g -->
    <mass value="0.072"/>
    <inertia ixx="1.717e-05" iyy="1.251e-05" izz="2.035e-05" ixy="2.12e-07" iyz="-0.0" ixz="0.0"/>
  </inertial>
  <visual>
    <origin xyz="0.01525 -0.0235 -0.2674" rpy="0 0 0"/>
    <geometry>
      <mesh filename="package://4-dof/meshes/MX-28T_R_v1__1__1.stl" scale="0.001 0.001 0.001"/>
    </geometry>
    <material name="silver"/>
  </visual>
  <collision>
    <origin xyz="0.01525 -0.0235 -0.2674" rpy="0 0 0"/>
    <geometry>
      <mesh filename="package://4-dof/meshes/MX-28T_R_v1__1__1.stl" scale="0.001 0.001 0.001"/>
    </geometry>
  </collision>
</link>

<link name="FR07-H101_v1_1">
  <inertial>
    <origin xyz="-3.365828433557125e-06 0.021380623885861517 6.089573290068984e-14" rpy="0 0 0"/>
    <mass value="0.025998108201265576"/>
    <inertia ixx="4e-06" iyy="9e-06" izz="1e-05" ixy="-0.0" iyz="0.0" ixz="0.0"/>
  </inertial>
  <visual>
    <origin xyz="0.00025 -0.053 -0.2824" rpy="0 0 0"/>
    <geometry>
      <mesh filename="package://4-dof/meshes/FR07-H101_v1_1.stl" scale="0.001 0.001 0.001"/>
    </geometry>
    <material name="silver"/>
  </visual>
  <collision>
    <origin xyz="0.00025 -0.053 -0.2824" rpy="0 0 0"/>
    <geometry>
      <mesh filename="package://4-dof/meshes/FR07-H101_v1_1.stl" scale="0.001 0.001 0.001"/>
    </geometry>
  </collision>
</link>

<link name="arm2_v2_1">
  <inertial>
    <origin xyz="-0.007777999999573574 0.03999999999999991 -0.007778000000000118" rpy="0 0 0"/>
    <!-- mass measured: arm2_v2_1 = 21.7g -->
    <mass value="0.0217"/>
    <inertia ixx="1.841e-05" iyy="4.818e-06" izz="1.841e-05" ixy="-0.0" iyz="-0.0" ixz="-0.0"/>
  </inertial>
  <visual>
    <origin xyz="-0.007528 -0.083 -0.290178" rpy="0 0 0"/>
    <geometry>
      <mesh filename="package://4-dof/meshes/arm2_v2_1.stl" scale="0.001 0.001 0.001"/>
    </geometry>
    <material name="silver"/>
  </visual>
  <collision>
    <origin xyz="-0.007528 -0.083 -0.290178" rpy="0 0 0"/>
    <geometry>
      <mesh filename="package://4-dof/meshes/arm2_v2_1.stl" scale="0.001 0.001 0.001"/>
    </geometry>
  </collision>
</link>

<link name="FR07-S101_v1_1">
  <inertial>
    <origin xyz="2.0689287956454638e-14 0.00221450679198662 0.000467333868896469" rpy="0 0 0"/>
    <mass value="0.011446844551351427"/>
    <inertia ixx="1e-06" iyy="2e-06" izz="2e-06" ixy="0.0" iyz="-0.0" ixz="-0.0"/>
  </inertial>
  <visual>
    <origin xyz="0.00025 -0.163 -0.2824" rpy="0 0 0"/>
    <geometry>
      <mesh filename="package://4-dof/meshes/FR07-S101_v1_1.stl" scale="0.001 0.001 0.001"/>
    </geometry>
    <material name="silver"/>
  </visual>
  <collision>
    <origin xyz="0.00025 -0.163 -0.2824" rpy="0 0 0"/>
    <geometry>
      <mesh filename="package://4-dof/meshes/FR07-S101_v1_1.stl" scale="0.001 0.001 0.001"/>
    </geometry>
  </collision>
</link>

<link name="MX-28T_R_v1_1">
  <inertial>
    <origin xyz="0.015031845145486136 0.024284471617669556 0.008499999976589567" rpy="0 0 0"/>
    <!-- mass from MX-28T spec sheet (robotis.com, 902-0067-000): 72g -->
    <mass value="0.072"/>
    <inertia ixx="1.717e-05" iyy="1.251e-05" izz="2.035e-05" ixy="2.12e-07" iyz="-0.0" ixz="0.0"/>
  </inertial>
  <visual>
    <origin xyz="0.01525 -0.169 -0.2739" rpy="0 0 0"/>
    <geometry>
      <mesh filename="package://4-dof/meshes/MX-28T_R_v1_1.stl" scale="0.001 0.001 0.001"/>
    </geometry>
    <material name="silver"/>
  </visual>
  <collision>
    <origin xyz="0.01525 -0.169 -0.2739" rpy="0 0 0"/>
    <geometry>
      <mesh filename="package://4-dof/meshes/MX-28T_R_v1_1.stl" scale="0.001 0.001 0.001"/>
    </geometry>
  </collision>
</link>

<link name="FR07-H101_v1__1__1">
  <inertial>
    <origin xyz="-3.3658284336170272e-06 0.021380623885861483 6.078471059822732e-14" rpy="0 0 0"/>
    <mass value="0.025998108201265576"/>
    <inertia ixx="4e-06" iyy="9e-06" izz="1e-05" ixy="-0.0" iyz="0.0" ixz="0.0"/>
  </inertial>
  <visual>
    <origin xyz="0.00025 -0.2048 -0.2824" rpy="0 0 0"/>
    <geometry>
      <mesh filename="package://4-dof/meshes/FR07-H101_v1__1__1.stl" scale="0.001 0.001 0.001"/>
    </geometry>
    <material name="silver"/>
  </visual>
  <collision>
    <origin xyz="0.00025 -0.2048 -0.2824" rpy="0 0 0"/>
    <geometry>
      <mesh filename="package://4-dof/meshes/FR07-H101_v1__1__1.stl" scale="0.001 0.001 0.001"/>
    </geometry>
  </collision>
</link>

<link name="racket_joint_v8_1">
  <inertial>
    <origin xyz="0.007777999999983611 0.01501142035517336 -0.0015451576233940778" rpy="0 0 0"/>
    <!-- TODO: measured mass is from racket_joint_v9_1 (13.3g + 13.2g = 26.5g); this link's mesh is
         still racket_joint_v8_1 and the STL shape looked different from the v9 parts weighed.
         Re-verify mass/inertia once the v9 mesh replaces v8 in this URDF. -->
    <mass value="0.0265"/>
    <inertia ixx="8.635e-06" iyy="1.349e-05" izz="1.053e-05" ixy="0.0" iyz="0.0" ixz="0.0"/>
  </inertial>
  <visual>
    <origin xyz="0.008028 -0.2348 -0.274622" rpy="0 0 0"/>
    <geometry>
      <mesh filename="package://4-dof/meshes/racket_joint_v8_1.stl" scale="0.001 0.001 0.001"/>
    </geometry>
    <material name="silver"/>
  </visual>
  <collision>
    <origin xyz="0.008028 -0.2348 -0.274622" rpy="0 0 0"/>
    <geometry>
      <mesh filename="package://4-dof/meshes/racket_joint_v8_1.stl" scale="0.001 0.001 0.001"/>
    </geometry>
  </collision>
</link>

<link name="pingpong_paddle_v5_1">
  <inertial>
    <origin xyz="6.7342507438505894e-15 -0.006399999999999961 -0.046816094811444026" rpy="0 0 0"/>
    <!-- mass measured: pingpong_paddle_v5_1 = 172.9g (with protective film still on, not peeled) -->
    <mass value="0.1729"/>
    <inertia ixx="0.0006375" iyy="0.0008405" izz="0.0002094" ixy="-0.0" iyz="0.0" ixz="-0.0"/>
  </inertial>
  <visual>
    <origin xyz="0.00025 -0.2561 -0.2484" rpy="0 0 0"/>
    <geometry>
      <mesh filename="package://4-dof/meshes/pingpong_paddle_v5_1.stl" scale="0.001 0.001 0.001"/>
    </geometry>
    <material name="silver"/>
  </visual>
  <collision>
    <origin xyz="0.00025 -0.2561 -0.2484" rpy="0 0 0"/>
    <geometry>
      <mesh filename="package://4-dof/meshes/pingpong_paddle_v5_1.stl" scale="0.001 0.001 0.001"/>
    </geometry>
  </collision>
</link>

<joint name="Rigid 4" type="fixed">
  <origin xyz="-0.06625 0.017 0.0148" rpy="0 0 0"/>
  <parent link="base_link"/>
  <child link="MX-64R_v1__2__1"/>
</joint>

<joint name="Rigid 5" type="fixed">
  <origin xyz="0.06625 0.017 0.0148" rpy="0 0 0"/>
  <parent link="base_link"/>
  <child link="MX-64R_v1__1__1"/>
</joint>

<joint name="Revolute 6" type="continuous">
  <origin xyz="0.0405 0.011 0.0453" rpy="0 0 0"/>
  <parent link="MX-64R_v1__2__1"/>
  <child link="FR05-H101_v1__1__1"/>
  <axis xyz="-1.0 0.0 0.0"/>
</joint>

<joint name="Rigid 7" type="fixed">
  <origin xyz="0.0255 0.0 0.036" rpy="0 0 0"/>
  <parent link="FR05-H101_v1__1__1"/>
  <child link="FR05-B101_v1_1"/>
</joint>

<joint name="Rigid 8" type="fixed">
  <origin xyz="-0.0173 0.004 0.006" rpy="0 0 0"/>
  <parent link="FR05-B101_v1_1"/>
  <child link="MX-64R_v1_1"/>
</joint>

<joint name="Revolute 9" type="revolute">
  <origin xyz="0.0173 -0.004 0.0405" rpy="0 0 0"/>
  <parent link="MX-64R_v1_1"/>
  <child link="FR05-H101_v1_1"/>
  <axis xyz="0.0 0.0 -1.0"/>
  <limit upper="0.523599" lower="-0.523599" effort="100" velocity="100"/>
</joint>

<joint name="Rigid 10" type="fixed">
  <origin xyz="-0.0235 0.0 0.0248" rpy="0 0 0"/>
  <parent link="FR05-H101_v1_1"/>
  <child link="arm_v9_1"/>
</joint>

<joint name="Rigid 11" type="fixed">
  <origin xyz="0.0235 -0.008 0.094" rpy="0 0 0"/>
  <parent link="arm_v9_1"/>
  <child link="FR07-S101_v1__1__1"/>
</joint>

<joint name="Rigid 12" type="fixed">
  <origin xyz="-0.015 0.0035 0.006" rpy="0 0 0"/>
  <parent link="FR07-S101_v1__1__1"/>
  <child link="MX-28T_R_v1__1__1"/>
</joint>

<joint name="Revolute 13" type="revolute">
  <origin xyz="0.015 0.0295 0.015" rpy="0 0 0"/>
  <parent link="MX-28T_R_v1__1__1"/>
  <child link="FR07-H101_v1_1"/>
  <axis xyz="-1.0 -0.0 -0.0"/>
  <limit upper="1.48353" lower="-2.007129" effort="100" velocity="100"/>
</joint>

<joint name="Rigid 19" type="fixed">
  <origin xyz="0.007778 0.03 0.007778" rpy="0 0 0"/>
  <parent link="FR07-H101_v1_1"/>
  <child link="arm2_v2_1"/>
</joint>

<joint name="Rigid 16" type="fixed">
  <origin xyz="-0.007778 0.08 -0.007778" rpy="0 0 0"/>
  <parent link="arm2_v2_1"/>
  <child link="FR07-S101_v1_1"/>
</joint>

<joint name="Rigid 17" type="fixed">
  <origin xyz="-0.015 0.006 -0.0085" rpy="0 0 0"/>
  <parent link="FR07-S101_v1_1"/>
  <child link="MX-28T_R_v1_1"/>
</joint>

<joint name="Revolute 18" type="revolute">
  <origin xyz="0.015 0.0358 0.0085" rpy="0 0 0"/>
  <parent link="MX-28T_R_v1_1"/>
  <child link="FR07-H101_v1__1__1"/>
  <axis xyz="-1.0 0.0 -0.0"/>
  <limit upper="2.094395" lower="-2.094395" effort="100" velocity="100"/>
</joint>

<joint name="Rigid 14" type="fixed">
  <origin xyz="-0.007778 0.03 -0.007778" rpy="0 0 0"/>
  <parent link="FR07-H101_v1__1__1"/>
  <child link="racket_joint_v8_1"/>
</joint>

<joint name="Rigid 15" type="fixed">
  <origin xyz="0.007778 0.0213 -0.026222" rpy="0 0 0"/>
  <parent link="racket_joint_v8_1"/>
  <child link="pingpong_paddle_v5_1"/>
</joint>

</robot>
